#VRML_SIM R2023b utf8

EXTERNPROTO "https://raw.githubusercontent.com/cyberbotics/webots/R2023b/projects/objects/backgrounds/protos/TexturedBackground.proto"
EXTERNPROTO "https://raw.githubusercontent.com/cyberbotics/webots/R2023b/projects/objects/backgrounds/protos/TexturedBackgroundLight.proto"
EXTERNPROTO "https://raw.githubusercontent.com/cyberbotics/webots/R2023b/projects/appearances/protos/BrushedAluminium.proto"
EXTERNPROTO "https://raw.githubusercontent.com/cyberbotics/webots/R2023b/projects/objects/floors/protos/RectangleArena.proto"
EXTERNPROTO "https://raw.githubusercontent.com/cyberbotics/webots/R2023b/projects/appearances/protos/MattePaint.proto"
EXTERNPROTO "https://raw.githubusercontent.com/cyberbotics/webots/R2023b/projects/objects/apartment_structure/protos/Wall.proto"
EXTERNPROTO "https://raw.githubusercontent.com/cyberbotics/webots/R2023b/projects/objects/factory/containers/protos/WoodenBox.proto"
EXTERNPROTO "https://raw.githubusercontent.com/cyberbotics/webots/R2023b/projects/objects/balls/protos/Ball.proto"
EXTERNPROTO "https://raw.githubusercontent.com/cyberbotics/webots/R2023b/projects/devices/hokuyo/protos/HokuyoUtm30lx.proto"

WorldInfo {
}
Viewpoint {
  orientation -0.15880256501589782 0.31135783186060934 0.9369301179295242 0.9970316805632489
  position -45.18814752241354 -121.45322851936281 51.64222843070218
  follow "robot"
}
DEF floor RectangleArena {
  name "floor"
  floorSize 290 290
  floorTileSize 1 1
  wallHeight 1
}
DEF hangar Solid {
  translation -150 -28 -1.2
  children [
    DEF HANGAR Shape {
      appearance BrushedAluminium {
      }
      geometry Mesh {
        url [
          "../../../assets/meshes/hangar/Hangar.stl"
        ]
      }
      castShadows FALSE
    }
  ]
  name "hangar"
  boundingObject USE HANGAR
}
DEF marker Ball {
}
Robot {
  translation 35 -10 0.0315
  rotation 0 0 1 3.14
  children [
    GPS {
      translation 0.8 0.503 0.1
    }
    Compass {
      translation 0.8 0.503 0.1
    }
    HokuyoUtm30lx {
      translation 0.82 0.503 0.11
    }
    Display {
      width 300
      height 300
    }
    DEF BODY Shape {
      appearance MattePaint {
        baseColor 1 0 0
      }
      geometry Mesh {
        url [
          "../../../assets/meshes/robot/NoBase_Robot.stl"
        ]
      }
      castShadows FALSE
    }
    DEF WHEEL_RIGHT_BACK_JOINT HingeJoint {
      jointParameters HingeJointParameters {
        axis 0 1 0
        anchor 0.183 0.128 0.092
      }
      device [
        RotationalMotor {
          name "wheel_right_back_joint"
          maxVelocity 30
          maxTorque 30
        }
        PositionSensor {
          name "wheel_right_back_joint_sensor"
        }
      ]
      endPoint DEF WHEEL_RIGHT_BACK_JOINT Solid {
        translation 0.18305658259599092 0.1278389999995415 0.09197384210560598
        rotation 0.9999999999975047 1.5859589833767297e-06 1.5733683171161843e-06 1.5707895802567726
        children [
          DEF WHEEL Shape {
            appearance MattePaint {
              baseColor 0 0 0
            }
            geometry Cylinder {
              height 0.12
              radius 0.125
            }
            castShadows FALSE
          }
        ]
        name "wheel_right_back_link"
        boundingObject USE WHEEL
        physics Physics {
        }
      }
    }
    DEF WHEEL_LEFT_BACK_JOINT HingeJoint {
      jointParameters HingeJointParameters {
        axis 0 1 0
        anchor 0.183 0.888 0.092
      }
      device [
        RotationalMotor {
          name "wheel_left_back_joint"
          maxVelocity 30
          maxTorque 30
        }
        PositionSensor {
          name "wheel_left_back_joint_sensor"
        }
      ]
      endPoint DEF WHEEL_LEFT_BACK_JOINT Solid {
        translation 0.18325303228887133 0.8878420000016956 0.09207778774720293
        rotation 0.9999999999997875 4.565167596811571e-07 4.654831560545965e-07 1.570787358849507
        children [
          USE WHEEL
        ]
        name "wheel_left_back_link"
        boundingObject USE WHEEL
        physics Physics {
        }
      }
    }
    DEF WHEEL_RIGHT_FRONT_JOINT HingeJoint {
      jointParameters HingeJointParameters {
        axis 0 1 0
        anchor 0.503 0.128 0.092
      }
      device [
        RotationalMotor {
          name "wheel_right_front_joint"
          maxVelocity 30
          maxTorque 30
        }
        PositionSensor {
          name "wheel_right_front_joint_sensor"
        }
      ]
      endPoint DEF WHEEL_RIGHT_FRONT_JOINT Solid {
        translation 0.5030585889630512 0.1280360000000993 0.09197384314127824
        rotation 0.9999999999975401 1.579920662126041e-06 1.556814450224009e-06 1.570814468999765
        children [
          USE WHEEL
        ]
        name "wheel_right_front_link"
        boundingObject USE WHEEL
        physics Physics {
        }
      }
    }
    DEF WHEEL_LEFT_FRONT_JOINT HingeJoint {
      jointParameters HingeJointParameters {
        axis 0 1 0
        anchor 0.503 0.888 0.092
      }
      device [
        RotationalMotor {
          name "wheel_left_front_joint"
          maxVelocity 30
          maxTorque 30
        }
        PositionSensor {
          name "wheel_left_front_joint_sensor"
        }
      ]
      endPoint DEF WHEEL_LEFT_FRONT_WHEEL Solid {
        translation 0.5028373243066255 0.8881110000012811 0.09207380710827354
        rotation 0.9999999999698003 -5.496409011143915e-06 -5.494452582541632e-06 1.5707748814564082
        children [
          USE WHEEL
        ]
        name "wheel_left_front_link"
        boundingObject USE WHEEL
        physics Physics {
        }
      }
    }
    DEF LEARJET35_JOINT HingeJoint {
      jointParameters HingeJointParameters {
        axis 0 0 1
        anchor 0.307 0.508 -0.09
      }
      endPoint DEF LEARJET35_JOINT Solid {
        translation 0.30826999348985257 0.5065999107653971 -0.08540981388119251
        rotation -0.7066686732325262 0.6501392824358091 -0.27917431777588725 0.004528440869519318
        children [
          DEF LEARJET35 Shape {
            appearance MattePaint {
            }
            geometry Mesh {
              url [
                "../../../assets/meshes/plane/Base_Plane.stl"
              ]
            }
            castShadows FALSE
          }
          DEF WHEEL_PLANE_LEFT_LEFT_JOINT HingeJoint {
            jointParameters HingeJointParameters {
              axis 0 1 0
              anchor -6.15 1.4 0.18
            }
            endPoint Solid {
              translation -6.15 1.4 0.18
              rotation 1 1.0061855557533147e-19 -1.0061892516860212e-19 1.5707999999999998
              children [
                DEF WHEEL_SHAPE Shape {
                  appearance MattePaint {
                    baseColor 0 0 0
                  }
                  geometry Cylinder {
                    height 0.18
                    radius 0.22
                  }
                }
              ]
              name "wheel_plane_left_left_link"
              boundingObject USE WHEEL_SHAPE
              physics Physics {
              }
            }
          }
          DEF WHEEL_PLANE_LEFT_RIGHT HingeJoint {
            jointParameters HingeJointParameters {
              axis 0 1 0
              anchor -6.15 1.11 0.18
            }
            endPoint Solid {
              translation -6.15 1.11 0.18
              rotation 1 -2.0603730630212574e-19 2.0603693670056008e-19 1.5707999999999998
              children [
                USE WHEEL_SHAPE
              ]
              name "wheel_plane_left_right_link"
              boundingObject USE WHEEL_SHAPE
              physics Physics {
              }
            }
          }
          DEF WHEEL_PLANE_RIGHT_RIGHT HingeJoint {
            jointParameters HingeJointParameters {
              axis 0 1 0
              anchor -6.15 -1.4 0.18
            }
            endPoint Solid {
              translation -6.15 -1.4 0.18
              rotation 1 4.0727941299601985e-19 -1.0062166247123895e-19 1.5707999999999998
              children [
                USE WHEEL_SHAPE
              ]
              name "wheel_plane_right_right_link"
              boundingObject USE WHEEL_SHAPE
              physics Physics {
              }
            }
          }
          DEF WHEEL_PLANE_RIGHT_LEFT HingeJoint {
            jointParameters HingeJointParameters {
              axis 0 1 0
              anchor -6.15 -1.11 0.18
            }
            endPoint Solid {
              translation -6.15 -1.11 0.18
              rotation 1 -1.1978637207431355e-19 -1.868724344733119e-19 1.5708
              children [
                USE WHEEL_SHAPE
              ]
              name "wheel_plane_right_left_link"
              boundingObject USE WHEEL_SHAPE
              physics Physics {
              }
            }
          }
        ]
        name "learjet35_link"
        boundingObject USE LEARJET35
        physics Physics {
          density 1
        }
      }
    }
  ]
  boundingObject USE BODY
  physics Physics {
    density 1
  }
  controller "BT_controller"
  supervisor TRUE
}
Wall {
  translation 0 -5 0
  rotation 1 0 0 1.5708
  size 0.2 3 12
}
WoodenBox {
  translation -10 -20 0.3
}
WoodenBox {
  translation -25 -25 0.3
  name "wooden box(1)"
}
WoodenBox {
  translation -55 -30 0.3
  name "wooden box(2)"
}
TexturedBackground {
}
TexturedBackgroundLight {
}
